[2025-05-10T17:38:59.361+0000] {taskinstance.py:1979} INFO - Dependencies all met for dep_context=non-requeueable deps ti=<TaskInstance: titanic_ml_pipeline.train_and_log_model scheduled__2024-07-28T00:00:00+00:00 [queued]>
[2025-05-10T17:38:59.376+0000] {taskinstance.py:1979} INFO - Dependencies all met for dep_context=requeueable deps ti=<TaskInstance: titanic_ml_pipeline.train_and_log_model scheduled__2024-07-28T00:00:00+00:00 [queued]>
[2025-05-10T17:38:59.376+0000] {taskinstance.py:2193} INFO - Starting attempt 1 of 2
[2025-05-10T17:38:59.426+0000] {taskinstance.py:2214} INFO - Executing <Task(PythonOperator): train_and_log_model> on 2024-07-28 00:00:00+00:00
[2025-05-10T17:38:59.444+0000] {standard_task_runner.py:60} INFO - Started process 2471 to run task
[2025-05-10T17:38:59.468+0000] {standard_task_runner.py:87} INFO - Running: ['***', 'tasks', 'run', 'titanic_ml_pipeline', 'train_and_log_model', 'scheduled__2024-07-28T00:00:00+00:00', '--job-id', '193', '--raw', '--subdir', 'DAGS_FOLDER/***_pipeline.py', '--cfg-path', '/tmp/tmpfism04j8']
[2025-05-10T17:38:59.480+0000] {standard_task_runner.py:88} INFO - Job 193: Subtask train_and_log_model
[2025-05-10T17:38:59.616+0000] {task_command.py:423} INFO - Running <TaskInstance: titanic_ml_pipeline.train_and_log_model scheduled__2024-07-28T00:00:00+00:00 [running]> on host e821d368632d
[2025-05-10T17:38:59.804+0000] {taskinstance.py:2510} INFO - Exporting env vars: AIRFLOW_CTX_DAG_OWNER='***' AIRFLOW_CTX_DAG_ID='titanic_ml_pipeline' AIRFLOW_CTX_TASK_ID='train_and_log_model' AIRFLOW_CTX_EXECUTION_DATE='2024-07-28T00:00:00+00:00' AIRFLOW_CTX_TRY_NUMBER='1' AIRFLOW_CTX_DAG_RUN_ID='scheduled__2024-07-28T00:00:00+00:00'
[2025-05-10T17:39:00.001+0000] {logging_mixin.py:188} WARNING - 2025/05/10 17:38:59 WARNING mlflow.utils.git_utils: Failed to import Git (the Git executable is probably not on your PATH), so Git SHA is not available. Error: Failed to initialize: Bad git executable.
The git executable must be specified in one of the following ways:
    - be included in your $PATH
    - be set via $GIT_PYTHON_GIT_EXECUTABLE
    - explicitly set via git.refresh(<full-path-to-git-executable>)

All git commands will error until this is rectified.

This initial message can be silenced or aggravated in the future by setting the
$GIT_PYTHON_REFRESH environment variable. Use one of the following values:
    - quiet|q|silence|s|silent|none|n|0: for no message or exception
    - warn|w|warning|log|l|1: for a warning message (logging level CRITICAL, displayed by default)
    - error|e|exception|raise|r|2: for a raised exception

Example:
    export GIT_PYTHON_REFRESH=quiet
[2025-05-10T17:39:00.493+0000] {warnings.py:109} WARNING - /home/***/.local/lib/python3.8/site-packages/mlflow/types/utils.py:407: UserWarning: Hint: Inferred schema contains integer column(s). Integer columns in Python cannot represent missing values. If your input data contains missing values at inference time, it will be encoded as floats and will cause a schema enforcement error. The best way to avoid this problem is to infer the model schema based on a realistic data sample (training dataset) that includes missing values. Alternatively, you can declare integer columns as doubles (float64) whenever these columns may have missing values. See `Handling Integers With Missing Values <https://www.mlflow.org/docs/latest/models.html#handling-integers-with-missing-values>`_ for more details.
  warnings.warn(

[2025-05-10T17:39:07.349+0000] {taskinstance.py:2728} ERROR - Task failed with exception
Traceback (most recent call last):
  File "/home/airflow/.local/lib/python3.8/site-packages/airflow/models/taskinstance.py", line 444, in _execute_task
    result = _execute_callable(context=context, **execute_callable_kwargs)
  File "/home/airflow/.local/lib/python3.8/site-packages/airflow/models/taskinstance.py", line 414, in _execute_callable
    return execute_callable(context=context, **execute_callable_kwargs)
  File "/home/airflow/.local/lib/python3.8/site-packages/airflow/operators/python.py", line 200, in execute
    return_value = self.execute_callable()
  File "/home/airflow/.local/lib/python3.8/site-packages/airflow/operators/python.py", line 217, in execute_callable
    return self.python_callable(*self.op_args, **self.op_kwargs)
  File "/opt/airflow/dags/airflow_pipeline.py", line 85, in train_and_log_model
  File "/home/airflow/.local/lib/python3.8/site-packages/pandas/core/generic.py", line 3772, in to_csv
    return DataFrameRenderer(formatter).to_csv(
  File "/home/airflow/.local/lib/python3.8/site-packages/pandas/io/formats/format.py", line 1186, in to_csv
    csv_formatter.save()
  File "/home/airflow/.local/lib/python3.8/site-packages/pandas/io/formats/csvs.py", line 240, in save
    with get_handle(
  File "/home/airflow/.local/lib/python3.8/site-packages/pandas/io/common.py", line 737, in get_handle
    check_parent_directory(str(handle))
  File "/home/airflow/.local/lib/python3.8/site-packages/pandas/io/common.py", line 600, in check_parent_directory
    raise OSError(rf"Cannot save file into a non-existent directory: '{parent}'")
OSError: Cannot save file into a non-existent directory: '/opt/***/data'
[2025-05-10T17:39:07.376+0000] {taskinstance.py:1149} INFO - Marking task as UP_FOR_RETRY. dag_id=titanic_ml_pipeline, task_id=train_and_log_model, execution_date=20240728T000000, start_date=20250510T173859, end_date=20250510T173907
[2025-05-10T17:39:07.410+0000] {standard_task_runner.py:107} ERROR - Failed to execute job 193 for task train_and_log_model (Cannot save file into a non-existent directory: '/opt/***/data'; 2471)
[2025-05-10T17:39:07.459+0000] {local_task_job_runner.py:234} INFO - Task exited with return code 1
[2025-05-10T17:39:07.499+0000] {taskinstance.py:3309} INFO - 0 downstream tasks scheduled from follow-on schedule check
